Workbook
Name CF: OFFSET('AET NPV'!$B$63,0,0,1,'AET NPV'!$C$6)
Name CF: OFFSET(#REF!,0,0,1,#REF!)
Name CumDiscCF: OFFSET('AET NPV'!$B$66,0,0,1,VALUE('AET NPV'!$C$6))
Name CumDiscCF: OFFSET(#REF!,0,0,1,VALUE(#REF!))
Name Rev_Stream: 'M2'!$D$74:$D$81
Name Rev_Stream: #REF!
Name Revenue: 'M2'!$D$74:$E$81
Name Revenue: #REF!
Name scenario: #REF!

Sheet Sheet1
B3: Current | C3: Weight % | D3: LHV (kJ/kg) DAF | E3: Moisture Content % | F3: NCV (kJ/kg) AR
B4: Food/ Kitchen | C4: 0.2728 | D4: 25000 | E4: 0.35 | F4: =D4*(1-E4) -> 16250
B5: Garden | C5: 0.0072 | D5: 25000 | E5: 0.35 | F5: =D5*(1-E5) -> 16250
B6: Recycable Paper | C6: 0.0757 | D6: 25000 | E6: 0.35 | F6: =D6*(1-E6) -> 16250
B7: Recycable Metal | C7: 0.0282 | D7: 0 | E7: 0 | F7: =D7*(1-E7) -> 0
B8: Recycable Plastic | C8: 0.0461 | D8: 30000 | E8: 0.1 | F8: =D8*(1-E8) -> 27000
B9: Recycable Glass | C9: 0.0244 | D9: 0 | E9: 0 | F9: =D9*(1-E9) -> 0
B10: Other Fine Material | C10: 0.0544 | D10: 0 | E10: 0.25 | F10: =D10*(1-E10) -> 0
B11: Other putrescible | C11: 0.0601 | D11: 25000 | E11: 0.35 | F11: =D11*(1-E11) -> 16250
B12: Organic other | C12: 0.0883 | D12: 25000 | E12: 0.35 | F12: =D12*(1-E12) -> 16250
B13: Household Hazardous | C13: 0.0068 | D13: 25000 | E13: 0.35 | F13: =D13*(1-E13) -> 16250
B14: Others | C14: 0.0149 | D14: 25000 | E14: 0.35 | F14: =D14*(1-E14) -> 16250
B15: Non-Recyclable Paper | C15: 0.1338 | D15: 25000 | E15: 0.35 | F15: =D15*(1-E15) -> 16250
... B17: Non-Recylable Plastic | C17: 0.1637 | D17: 30000 | E17: 0.1 | F17: =D17*(1-E17) -> 27000
B18: Non-Recyclable Glass | C18: 0.003 | D18: 0 | E18: 0 | F18: =D18*(1-E18) -> 0 | J18: Feedstock Handling and Sorting | O18: Gasification | U18: Power Gen
C20: =SUM(C4:C18) -> 0.9999 | D20: =SUMPRODUCT(C4:C18,D4:D18) -> 22784 | E20: =SUMPRODUCT(C4:C18,E4:E18) -> 0.26544 | F20: =SUMPRODUCT(C4:C18,F4:F18) -> 16383.1 | J20: Annual Capacity | K20: 30000 | O20: Annual Capacity | P20: =(J40+J41)/1000*K20 -> 26082 | U20: Annual Capacity (kwh) | V20: 1000
J21: $/tonne annual cap | K21: 375 | O21: $/tonne annual cap | P21: 550 | U21: $/kwh | V21: 750
B22: Residual | C22: Weight % | D22: LHV (kJ/kg) DAF | E22: Moisture Content % | F22: NCV (kJ/kg) AR | J22: CAPEX | K22: =K20*K21 -> 11250000 | O22: CAPEX | P22: =P20*P21 -> 14345100 | U22: CAPEX | V22: =V20*V21 -> 750000
B23: Other Fine Material | C23: =100*C10/(100*SUM($C$10:$C$18)) -> 0.099725023 | D23: =D10 -> 0 | E23: =E10 -> 0.25 | F23: =F10 -> 0 | J23: Rate | K23: 0.12 | O23: Rate | P23: 0.08 | U23: Rate | V23: 0.08
B24: Other putrescible | C24: =100*C11/(100*SUM($C$10:$C$18)) -> 0.11017415 | D24: =D11 -> 25000 | E24: =E11 -> 0.35 | F24: =F11 -> 16250 | J24: Periods | K24: 15 | O24: Periods | P24: 15 | U24: Periods | V24: 15
B25: Organic other | C25: =100*C12/(100*SUM($C$10:$C$18)) -> 0.16186984 | D25: =D12 -> 25000 | E25: =E12 -> 0.35 | F25: =F12 -> 16250 | J25: PMT | K25: =PMT(K23,K24,K21*K20) -> -1651772.7 | L25: =K25/K20 -> -55.05909 | O25: PMT | P25: =PMT(P23,P24,P21*P20) -> -1675931.5 | U25: PMT | V25: =PMT(V23,V24,V21*V20) -> -87622.159
B26: Household Hazardous | C26: =100*C13/(100*SUM($C$10:$C$18)) -> 0.012465628 | D26: =D13 -> 25000 | E26: =E13 -> 0.35 | F26: =F13 -> 16250 | J26: PMT/kg | K26: =K25/(K20*1000) -> -0.05505909 | O26: PMT/kg | P26: =P25/(P20*1000) -> -0.06425625 | U26: PMT/kg | V26: =V25/(V20*1000) -> -0.087622159
B27: Others | C27: =100*C14/(100*SUM($C$10:$C$18)) -> 0.02731439 | D27: =D14 -> 25000 | E27: =E14 -> 0.35 | F27: =F14 -> 16250
B28: Non-Recyclable Paper | C28: =100*C15/(100*SUM($C$10:$C$18)) -> 0.24527956 | D28: =D15 -> 25000 | E28: =E15 -> 0.35 | F28: =F15 -> 16250 | J28: OPEX% of CAPEX | K28: 0.2 | O28: OPEX% of CAPEX | P28: 0.1 | U28: OPEX% of CAPEX | V28: 0.2
B29: Non-Recyclable Metal | C29: =100*C16/(100*SUM($C$10:$C$18)) -> 0.037580202 | D29: =D16 -> 0 | E29: =E16 -> 0 | F29: =F16 -> 0 | J29: OPEX | K29: =-K28*K22 -> -2250000 | L29: =K29/K20 -> -75 | O29: OPEX | P29: =-P28*P22 -> -1434510 | U29: OPEX | V29: =-V28*V22 -> -150000
B30: Non-Recylable Plastic | C30: =100*C17/(100*SUM($C$10:$C$18)) -> 0.30009166 | D30: =D17 -> 30000 | E30: =E17 -> 0.1 | F30: =F17 -> 27000 | J30: OPEX/kg | K30: =K29/(K20*1000) -> -0.075 | O30: OPEX/kg | P30: =P29/(P20*1000) -> -0.055 | U30: OPEX/kg | V30: =V29/(V20*1000) -> -0.15
B31: Non-Recyclable Glass | C31: =100*C18/(100*SUM($C$10:$C$18)) -> 0.0054995417 | D31: =D18 -> 0 | E31: =E18 -> 0 | F31: =F18 -> 0
A33: 1000 | B33: 0 | C33: =SUM(C23:C31) -> 1 | D33: =SUMPRODUCT(C23:C31,D23:D31) -> 22930.339 | E33: =SUMPRODUCT(C23:C31,E23:E31) -> 0.24992667 | F33: =SUMPRODUCT(C23:C31,F23:F31) -> 17155.408
P34: kg per Tonne | Q34: Value ($/kg) | R34: Total Value per Tonne | S34: Total Value
B35: Fines | C35: Weight | D35: LHV (kJ/kg) DAF | E35: Moisture Content % | F35: NCV (kJ/kg) AR | J35: Kg per Tonne | K35: Value ($/kg) | L35: Total Value per Tonne | M35: Total Value | O35: Light SRF | P35: =J40/SUM(J40:J41)*1000 -> 482.28663 | Q35: =-K40 -> 0.21316346 | R35: =P35*Q35 -> 102.80589 | S35: =R35*$P$20 -> 2681383.1 | U35: Energy/ Gas Gen (GJ)
B36: Other Fine Material | C36: =IF($B$33=0,$A$33*INDEX($C$4:$F$18,MATCH(B36,$B$4:$B$18,0),1),$A$33*IFERROR(INDEX($C$23:$F$31,MATCH(B36,$B$23:$B$31,0),1),0)) -> 54.4 | D36: =IFERROR(INDEX($D$4:$D$18,MATCH($B36,$B$4:$B$18,0)),0) -> 0 | E36: =IFERROR(INDEX($E$4:$E$18,MATCH($B36,$B$4:$B$18,0)),0) -> 0.25 | F36: =D36*(1-E36) -> 0 | I36: Gate Fee | J36: =1000 -> 1000 | K36: 0.2 | L36: =J36*K36 -> 200 | M36: =L36*$K$20 -> 6000000 | O36: Heacy SRF | P36: =J41/SUM(J40:J41)*1000 -> 517.71337 | Q36: =-K41 -> 0.1625 | R36: =P36*Q36 -> 84.128422 | S36: =R36*$P$20 -> 2194237.5
I37: Fines | J37: =C36 -> 54.4 | K37: -0.16 | L37: =J37*K37 -> -8.704 | M37: =L37*$K$20 -> -261120 | O37: Char | P37: =0.3*SUM(P35:P36) -> 300 | Q37: -0.16 | R37: =P37*Q37 -> -48 | S37: =R37*$P$20 -> -1251936
B38: Metals | C38: Weight | D38: LHV (kJ/kg) DAF | E38: Moisture Content % | F38: NCV (kJ/kg) AR | I38: Metals | J38: =SUM(C39:C40) -> 48.7 | K38: 0.2 | L38: =J38*K38 -> 9.74 | M38: =L38*$K$20 -> 292200 | O38: Energy/ Gas Gen (GJ) | P38: =(P35*F52/1000/1000+P36*F61/1000/1000)*0.7 -> 13.085402 | Q38: 10 | R38: =P38*Q38 -> 130.85402 | S38: =R38*$P$20 -> 3412934.5
B39: Recycable Metal | C39: =IF($B$33=0,$A$33*INDEX($C$4:$F$18,MATCH(B39,$B$4:$B$18,0),1),$A$33*IFERROR(INDEX($C$23:$F$31,MATCH(B39,$B$23:$B$31,0),1),0)) -> 28.2 | D39: =IFERROR(INDEX($D$4:$D$18,MATCH($B39,$B$4:$B$18,0)),0) -> 0 | E39: =IFERROR(INDEX($E$4:$E$18,MATCH($B39,$B$4:$B$18,0)),0) -> 0 | F39: =D39*(1-E39) -> 0 | I39: Glass | J39: =SUM(C43:C44) -> 27.4 | K39: 0.03 | L39: =J39*K39 -> 0.822 | M39: =L39*$K$20 -> 24660 | O39: CO2 | P39: 1000 | Q39: 0.015 | R39: =P39*Q39 -> 15 | S39: =R39*$P$20 -> 391230
B40: Non-Recyclable Metal | C40: =IF($B$33=0,$A$33*INDEX($C$4:$F$18,MATCH(B40,$B$4:$B$18,0),1),$A$33*IFERROR(INDEX($C$23:$F$31,MATCH(B40,$B$23:$B$31,0),1),0)) -> 20.5 | D40: =IFERROR(INDEX($D$4:$D$18,MATCH($B40,$B$4:$B$18,0)),0) -> 0 | E40: =IFERROR(INDEX($E$4:$E$18,MATCH($B40,$B$4:$B$18,0)),0) -> 0 | F40: =D40*(1-E40) -> 0 | I40: Light SRF | J40: =SUM(C48:C51) -> 419.3 | K40: =G52 -> -0.21316346 | L40: =J40*K40 -> -89.379438 | M40: =L40*$K$20 -> -2681383.1 | O40: Total Value per Tonne of Feed | P40: 1000 | Q40: =R40/P40 -> 0.28478833 | R40: =SUM(R35:R39) -> 284.78833 | S40: =R40*$P$20 -> 7427849.1
I41: Heavy SRF | J41: =SUM(C55:C60) -> 450.1 | K41: =G61 -> -0.1625 | L41: =J41*K41 -> -73.14125 | M41: =L41*$K$20 -> -2194237.5 | O41: CAPEX | P41: 1000 | Q41: =P26 -> -0.06425625 | R41: =P41*Q41 -> -64.25625 | S41: =R41*$P$20 -> -1675931.5
B42: Glass | I42: Avg Prod Value | J42: 1000 | K42: =SUMPRODUCT(J37:J41,K37:K41)/J42 -> -0.16066269 | L42: =J42*K42 -> -160.66269 | M42: =L42*$K$20 -> -4819880.6 | O42: OPEX | P42: 1000 | Q42: =P30 -> -0.055 | R42: =P42*Q42 -> -55 | S42: =R42*$P$20 -> -1434510
B43: Recycable Glass | C43: =IF($B$33=0,$A$33*INDEX($C$4:$F$18,MATCH(B43,$B$4:$B$18,0),1),$A$33*IFERROR(INDEX($C$23:$F$31,MATCH(B43,$B$23:$B$31,0),1),0)) -> 24.4 | D43: =IFERROR(INDEX($D$4:$D$18,MATCH($B43,$B$4:$B$18,0)),0) -> 0 | E43: =IFERROR(INDEX($E$4:$E$18,MATCH($B43,$B$4:$B$18,0)),0) -> 0 | F43: =D43*(1-E43) -> 0 | I43: Total Value per Tonne of Feed | J43: 1000 | K43: =K36+K42 -> 0.039337312 | L43: =J43*K43 -> 39.337312 | M43: =L43*$K$20 -> 1180119.4 | O43: Margin | P43: 1000 | Q43: =Q40+Q41+Q42 -> 0.16553208 | R43: =P43*Q43 -> 165.53208 | S43: =R43*$P$20 -> 4317407.6
B44: Non-Recyclable Glass | C44: =IF($B$33=0,$A$33*INDEX($C$4:$F$18,MATCH(B44,$B$4:$B$18,0),1),$A$33*IFERROR(INDEX($C$23:$F$31,MATCH(B44,$B$23:$B$31,0),1),0)) -> 3 | D44: =IFERROR(INDEX($D$4:$D$18,MATCH($B44,$B$4:$B$18,0)),0) -> 0 | E44: =IFERROR(INDEX($E$4:$E$18,MATCH($B44,$B$4:$B$18,0)),0) -> 0 | F44: =D44*(1-E44) -> 0 | I44: CAPEX | J44: 1000 | K44: =K26 -> -0.05505909 | L44: =J44*K44 -> -55.05909 | M44: =L44*$K$20 -> -1651772.7
I45: OPEX | J45: 1000 | K45: =K30 -> -0.075 | L45: =J45*K45 -> -75 | M45: =L45*$K$20 -> -2250000
...

Sheet Sheet3
D4: Low Case ($/T) | E4: High Case ($/T)
C5: CAPEX | D5: -150 | E5: -110 | F5: =E5-D5 -> 40
C6: OPEX | D6: -110 | E6: -90 | F6: =E6-D6 -> 20
C7: Recovered Material | D7: -5 | E7: 11 | F7: =E7-D7 -> 16
C8: CO2 linked to Energy | D8: 0 | E8: =45000*16/30000 -> 24 | F8: =E8-D8 -> 24
C9: Char | D9: -30 | E9: 10 | F9: =E9-D9 -> 40
C10: Gate Fee* CPI Adj | D10: 165 | E10: 165
C11: CAPEX Savings | D11: 40
C12: OPEX Savings | D12: 20
C13: Imprv. Recovered Material Markets | D13: 16
C14: CO2 Credits Obtained | D14: 45
C15: Imprv. Char Markets | D15: 40
C18: Marigin | D18: =SUM(D5:D10) -> -130 | E18: =SUM(E5:E10) -> 10
D22: =165/295 -> 0.55932203 | E22: =165/200 -> 0.825

Sheet AET NPV
A1: Equity Analysis of a Project
E2: INPUT SHEET: USER ENTERS ALL BOLD NUMBERS
A3: INITIAL INVESTMENT | E3: CASHFLOW DETAILS | I3: DISCOUNT RATE
A4: Initial Investment= | C4: =Sheet1!K22 -> 11250000 | E4: Tax rate on net income= | G4: 0.3 | I4: Approach(1:Direct;2:CAPM)= | K4: 1
A5: Opportunity cost (if any)= | C5: 0 | I5: 1. Discount rate = | K5: 0.12
A6: Lifetime of the investment | C6: =Sheet1!K24 -> 15 | I6: 2a. Beta | K6: 1
A7: Salvage Value at end of project= | C7: 0 | I7: b. Riskless rate= | K7: 0.04
A8: Deprec. method(1:St.line;2:DDB)= | C8: 1 | I8: c. Market risk premium = | K8: 0.08
A9: Tax Credit (if any )= | C9: 0 | I9: d. Debt Ratio = | K9: 0.5
A10: Other invest.(non-depreciable)= | C10: 0 | I10: e. Cost of Borrowing = | K10: 0.08
I11: Discount rate used= | K11: =IF(K4=1,K5,(K7+K6*K8)*(1-K9)+K10*(1-G4)*K9) -> 0.12
A12: WORKING CAPITAL
A13: Initial Investment in Work. Cap= | C13: 0
A14: Working Capital as % of Rev= | C14: 0
A15: Salvageable fraction at end= | C15: 0
A17: GROWTH RATES
C18: 1 | D18: 2 | E18: 3 | F18: 4 | G18: 5 | H18: 6 | I18: 7 | J18: 8 | K18: 9 | L18: 10 | M18: 11 | N18: 12 | O18: 13 | P18: 14 | Q18: 15 | R18: 16 | S18: 17 | T18: 18 | U18: 19 | V18: 20
A19: Revenues | C19: Do not enter | D19: =(D46/C46)-1 -> 0.12710579 | E19: =(E46/D46)-1 -> 0.11559113 | F19: =(F46/E46)-1 -> 0.1062046 | G19: =(G46/F46)-1 -> 0.0984083 | H19: =(H46/G46)-1 -> 0.091831523 | I19: =(I46/H46)-1 -> 0.086210473 | J19: =(J46/I46)-1 -> 0.081352313 | K19: =(K46/J46)-1 -> 0.077112815 | ... V19: =(V46/U46)-1 -> #DIV/0!
A20: +Gate Fee | D20: 0.025 | E20: =D20 -> 0.025 | F20: =E20 -> 0.025 | G20: =F20 -> 0.025 | H20: =G20 -> 0.025 | I20: =H20 -> 0.025 | J20: =I20 -> 0.025 | K20: =J20 -> 0.025 | L20: =K20 -> 0.025 | ... V20: =U20 -> 0.025
A21: +Recycable Material | D21: 0 | E21: =D21 -> 0 | F21: =E21 -> 0 | G21: =F21 -> 0 | H21: =G21 -> 0 | I21: =H21 -> 0 | J21: =I21 -> 0 | K21: =J21 -> 0 | L21: =K21 -> 0 | ... V21: =U21 -> 0
A22: +Energy | D22: 0 | E22: =D22 -> 0 | F22: =E22 -> 0 | G22: =F22 -> 0 | H22: =G22 -> 0 | I22: =H22 -> 0 | J22: =I22 -> 0 | K22: =J22 -> 0 | L22: =K22 -> 0 | ... V22: =U22 -> 0
A23: +Other | D23: 0 | E23: =D23 -> 0 | F23: =E23 -> 0 | G23: =F23 -> 0 | H23: =G23 -> 0 | I23: =H23 -> 0 | J23: =I23 -> 0 | K23: =J23 -> 0 | L23: =K23 -> 0 | ... V23: =U23 -> 0
A24: Operating Expenses | C24: Do not enter | D24: =(D51/C51)-1 -> 0.025 | E24: =(E51/D51)-1 -> 0.025 | F24: =(F51/E51)-1 -> 0.025 | G24: =(G51/F51)-1 -> 0.025 | H24: =(H51/G51)-1 -> 0.025 | I24: =(I51/H51)-1 -> 0.025 | J24: =(J51/I51)-1 -> 0.025 | K24: =(K51/J51)-1 -> 0.025 | ... V24: =(V51/U51)-1 -> #DIV/0!
A25: -O&M Variable | D25: 0.025 | E25: =D25 -> 0.025 | F25: =E25 -> 0.025 | G25: =F25 -> 0.025 | H25: =G25 -> 0.025 | I25: =H25 -> 0.025 | J25: =I25 -> 0.025 | K25: =J25 -> 0.025 | L25: =K25 -> 0.025 | ... V25: =U25 -> 0.025
A26: -O&M Fixed | D26: 0.025 | E26: =D26 -> 0.025 | F26: =E26 -> 0.025 | G26: =F26 -> 0.025 | H26: =G26 -> 0.025 | I26: =H26 -> 0.025 | J26: =I26 -> 0.025 | K26: =J26 -> 0.025 | L26: =K26 -> 0.025 | ... V26: =U26 -> 0.025
A27: -Other | D27: 0 | E27: =D27 -> 0 | F27: =E27 -> 0 | G27: =F27 -> 0 | H27: =G27 -> 0 | I27: =H27 -> 0 | J27: =I27 -> 0 | K27: =J27 -> 0 | L27: =K27 -> 0 | ... V27: =U27 -> 0
F29: YEAR
B30: 0 | C30: 1 | D30: 2 | E30: 3 | F30: 4 | G30: 5 | H30: 6 | I30: 7 | J30: 8 | K30: 9 | L30: 10 | M30: 11 | N30: 12 | O30: 13 | P30: 14 | Q30: 15 | R30: 16 | S30: 17 | T30: 18 | U30: 19 | V30: 20
A31: INVESTMENTS
A32: Investment | B32: =C4 -> 11250000
A33: - Tax Credit | B33: =C4*C9 -> 0
A34: Net Investment | B34: =B32-B33 -> 11250000
A35: + Working Cap | B35: =C13 -> 0
A36: + Opp. Cost | B36: =C5 -> 0
A37: + Other invest. | B37: =C10 -> 0
A38: Investments | B38: =B34+B35+B36+B37 -> 11250000
A40: SALVAGE VALUE
A41: Equipment | C41: =IF(C30=$C$6,$C$7,0) -> 0 | D41: =IF(D30=$C$6,$C$7,0) -> 0 | E41: =IF(E30=$C$6,$C$7,0) -> 0 | F41: =IF(F30=$C$6,$C$7,0) -> 0 | G41: =IF(G30=$C$6,$C$7,0) -> 0 | H41: =IF(H30=$C$6,$C$7,0) -> 0 | I41: =IF(I30=$C$6,$C$7,0) -> 0 | J41: =IF(J30=$C$6,$C$7,0) -> 0 | ... V41: =IF(V30=$C$6,$C$7,0) -> 0
A42: Working Capital | C42: =IF(C30=$C$6,($C$13+SUM($C$61:$V$61))*$C$15,0) -> 0 | D42: =IF(D30=$C$6,($C$13+SUM($C$61:$V$61))*$C$15,0) -> 0 | E42: =IF(E30=$C$6,($C$13+SUM($C$61:$V$61))*$C$15,0) -> 0 | F42: =IF(F30=$C$6,($C$13+SUM($C$61:$V$61))*$C$15,0) -> 0 | G42: =IF(G30=$C$6,($C$13+SUM($C$61:$V$61))*$C$15,0) -> 0 | H42: =IF(H30=$C$6,($C$13+SUM($C$61:$V$61))*$C$15,0) -> 0 | I42: =IF(I30=$C$6,($C$13+SUM($C$61:$V$61))*$C$15,0) -> 0 | J42: =IF(J30=$C$6,($C$13+SUM($C$61:$V$61))*$C$15,0) -> 0 | ... V42: =IF(V30=$C$6,($C$13+SUM($C$61:$V$61))*$C$15,0) -> 0
A44: OPERATING CASHFLOWS
...

Sheet M2
A1: Unprocessed Feed | Q1: Model Parameters | V1: Revenue Assumptions
A2: Annual Quantity | B2: =#REF!*#REF!*#REF!/1000 -> #REF! | C2: MT/yr | D2: Ratability (Days/ Year) | E2: =Z18 -> 320 | G2: Feed Composition (wt % wb) | J2: Non - Combustible | Q2: Parameter | R2: Value | S2: Units | T2: Comments | V2: Stream | W2: Value | X2: Units | Y2: Comments
A3: Maximum Rate | B3: =B5*E3 -> #REF! | C3: MT/hr | D3: Maximum (% of Typical) | E3: 1.15 | G3: Moisture | H3: Volatile Matter | I3: Fixed Carbon | J3: Ash | K3: Ferrous Metals | L3: Aluminium | N3: LHV (kJ/kg) DAF | O3: NCV (kJ/kg) AR | Q3: Enthalpy Change h2O Drier | R3: 2573 | S3: kJ/kg | T3: 25 to 100 deg C steam | V3: Thermal Value | W3: 10 | X3: AUD/GJ
A4: Minimum Rate | B4: =B5*E4 -> #REF! | C4: MT/hr | D4: Minimum (% of Typical) | E4: 0.85 | G4: =#REF! -> #REF! | H4: =#REF! -> #REF! | I4: =#REF! -> #REF! | J4: =#REF! -> #REF! | K4: =#REF! -> #REF! | L4: =#REF! -> #REF! | N4: =#REF! -> #REF! | O4: =(((N4/1000)*(1-(J4*(1/(1-G4)))/1)*((1-G4)/1))-(0.02443*G4))*1000 -> #REF! | Q4: Specific Heat Drier Gas | R4: 1.05 | S4: kJ/kg/C | V4: Char Value | W4: 0.2 | X4: AUD/kg
A5: Typical Rate | B5: =B2/E2/24 -> #REF! | C5: MT/hr | D5: Natural Ratability (Days/year) | E5: 320 | I5: Total | J5: =SUM(J4:L4) -> #REF! | Q5: Enthalpy Change feed | R5: =1.3*(G66-25) -> 552.5 | S5: kJ/kg | T5: Linked to Reactor Temp | V5: Waste Disposal Fee/ (cost) | W5: -0.05 | X5: AUD/kg
A6: Storage | B6: =(E2-E5)*24*B5*1000/R12 -> #REF! | C6: m3 | G6: =G4*$B$5*1000 -> #REF! | H6: =H4*$B$5*1000 -> #REF! | I6: =I4*$B$5*1000 -> #REF! | J6: =J4*$B$5*1000 -> #REF! | K6: =K4*$B$5*1000 -> #REF! | L6: =L4*$B$5*1000 -> #REF! | N6: =B5*1000-G6-J6 -> #REF! | Q6: Enthalpy Change h2O Gasifier | R6: =4050-(1.5*(1200-H66)) -> 3525 | S6: kJ/kg | T6: Linked to Ox Temp | V6: Electricity Value | W6: 0.15 | X6: AUD/kWh
Q7: Air Required | R7: =(1/12)/0.21*29*R10 -> 13.809524 | S7: kg/kg | T7: of fuel burnt | V7: Water Value | W7: 0.001 | X7: AUD/kg
A8: Supplemental Feed | Q8: Enthalpy Change Air | R8: =1*(H66-25) -> 825 | S8: kJ/kg | T8: Linked to Ox Temp | V8: Supp Feed Value/ (Cost) | W8: 0 | X8: AUD/kg
A9: Annual Quantity | B9: 0 | C9: MT/yr | D9: Ratability (Days/ Year) | E9: =Z18 -> 320 | G9: Feed Composition (wt % wb) | J9: Non - Combustible | Q9: Heat Loss | R9: 0.03 | S9: % | T9: % of Qfuel | V9: GHG Credit Value | W9: 0.2 | X9: AUD/kg
A10: Maximum Rate | B10: =B12*E10 -> 0 | C10: MT/hr | D10: Maximum (% of Typical) | E10: 1.15 | G10: Moisture | H10: Volatile Matter | I10: Fixed Carbon | J10: Ash | K10: Ferrous Metals | L10: Aluminium | N10: LHV (kJ/kg) DAF | O10: NCV (kJ/kg) AR | Q10: XS Air | R10: =I66 -> 1.2 | S10: % | T10: Linked to Gasification Unit | V10: Dewatered Product Value | W10: 0 | X10: AUD/kg
A11: Minimum Rate | B11: =B12*E11 -> 0 | C11: MT/hr | D11: Minimum (% of Typical) | E11: 0.85 | G11: 0.1 | H11: =(1-G11)*0.8 -> 0.72 | I11: =(1-G11)*0.193 -> 0.1737 | J11: =(1-G11)*0.7% -> 0.0063 | K11: 0 | L11: 0 | N11: 18800 | O11: =(((N11/1000)*(1-(J11*(1/(1-G11)))/1)*((1-G11)/1))-(0.02443*G11))*1000 -> 16799.117 | Q11: Dryer Efficiency | R11: 3300 | S11: kJ/kg | T11: of water removal | V11: Dried Product Value | W11: 0.1 | X11: AUD/kg
A12: Typical Rate | B12: =B9/E9/24 -> 0 | C12: MT/hr | D12: Natural Ratability (Days/year) | E12: 120 | I12: Total | J12: =SUM(J11:L11) -> 0.0063 | Q12: Bulk Density Feed | R12: 700 | S12: kg/m3 | V12: Weighted Feed Value/ (Cost) | W12: =(B2*W5+B9*W8)/(B2+B9) -> #REF! | X12: AUD/kg
A13: Storage | B13: =(E9-E12)*24*B12*1000/R12 -> 0 | C13: m3 | G13: =G11*$B$12*1000 -> 0 | H13: =H11*$B$12*1000 -> 0 | I13: =I11*$B$12*1000 -> 0 | J13: =J11*$B$12*1000 -> 0 | K13: =K11*$B$12*1000 -> 0 | L13: =L11*$B$12*1000 -> 0 | N13: =B12*1000-G13-J13 -> 0 | V13: Metal Value | W13: 1 | X13: AUD/kg
Q14: Cost Assumptions
A15: Blended Feed | Q15: Parameter | R15: Value | S15: Units | T15: Comments | V15: O&M Summary | Y15: O&M Assumptions
A16: Annual Quantity | B16: =B2+B9 -> #REF! | C16: MT/yr | D16: Ratability (Days/ Year) | E16: =Z18 -> 320 | G16: Feed Composition (wt % wb) | J16: Non - Combustible | Q16: Storage Cost | R16: 50 | S16: $/m3 | V16: Mgmt OvHd | W16: =Z28*W17 -> 45000 | Y16: Parameter | Z16: Value | AA16: Units | AB16: Comments
A17: Maximum Rate | B17: =B3+B10 -> #REF! | C17: MT/hr | D17: Maximum (% of Typical) | E17: =B17/B19 -> #REF! | G17: Moisture | H17: Volatile Matter | I17: Fixed Carbon | J17: Ash | K17: Ferrous Metals | L17: Aluminium | N17: LHV (kJ/kg) DAF | O17: NCV (kJ/kg) AR | Q17: TIC Electrical Gen | R17: 3750 | S17: AUD/kW | V17: Direct SWB | W17: =Z25*Z26 -> 450000 | Y17: Hrs/ Day | Z17: 24
A18: Minimum Rate | B18: =B4+B11 -> #REF! | C18: MT/hr | D18: Minimum (% of Typical) | E18: =B18/B19 -> #REF! | G18: =G20/SUM($G$20:$L$20) -> #REF! | H18: =H20/SUM($G$20:$L$20) -> #REF! | I18: =I20/SUM($G$20:$L$20) -> #REF! | J18: =J20/SUM($G$20:$L$20) -> #REF! | K18: =K20/SUM($G$20:$L$20) -> #REF! | L18: =L20/SUM($G$20:$L$20) -> #REF! | N18: =(N4*N6+N11*N13)/(N6+N13) -> #REF! | O18: =(((N18/1000)*(1-(J18*(1/(1-G18)))/1)*((1-G18)/1))-(0.02443*G18))*1000 -> #REF! | Q18: Exchange Rate | R18: 1.5 | S18: USD/AUD | Y18: Days/ Year | Z18: 320
A19: Typical Rate | B19: =B5+B12 -> #REF! | C19: MT/hr | D19: Natural Ratability (Days/year) | E19: 320 | I19: Total | J19: =SUM(J18:L18) -> #REF! | Q19: Interest Rate | R19: 0.08 | S19: % | V19: Energy Costs | W19: =Z30*W6*Z17*Z18 -> #REF! | Y19: Number of Ops positions | Z19: 1
A20: Storage | B20: =(E16-E19)*24*B19*1000/R12 -> #REF! | C20: m3 | G20: =G6+G13 -> #REF! | H20: =H6+H13 -> #REF! | I20: =I6+I13 -> #REF! | J20: =J6+J13 -> #REF! | K20: =K6+K13 -> #REF! | L20: =L6+L13 -> #REF! | N20: =N6+N13 -> #REF! | Q20: Loan Length | R20: 10 | S20: years | V20: Other | W20: =Z17*Z18*Z31 -> 76800 | Y20: hrs per Shift | Z20: 12
Q21: Leverage | R21: 2 | Y21: shifts per week | Z21: =24*7/Z20 -> 14
Q22: CAPEX Discount | R22: 0 | S22: % | V22: Direct Maintenance | W22: =Z33*(B90-B88) -> #REF! | Y22: working hours a week | Z22: 40
A23: Dewater | E23: Dewatered Product | Q23: Water Treatment Cost | R23: 0.1 | S23: AUD/m3 | V23: Accrued Maintenance | W23: =Z34*(B90-B88) -> #REF! | Y23: maximum shifts per person | Z23: =ROUND(Z22/Z20,0) -> 3
A24: Feed to Dewatering | B24: 0 | C24: % of Blended | E24: Rate | F24: =B27+B30 -> #REF! | G24: kg/hr | H24: Sold | I24: =F24*F25 -> #REF! | J24: kg/hr | Y24: Required Number of shift groups | Z24: =ROUND(Z21/Z23,0) -> 5
A25: %DS | B25: 0.3 | C25: % | E25: Sale Fraction | F25: 0 | G25: % | H25: NCV AR | I25: =(((N18/1000)*(1-(H29*(1/(1-E29)))/1)*((1-E29)/1))-(0.02443*E29))*1000 -> #REF! | J25: kJ/kg | Y25: number of Operators | Z25: =Z24*Z19 -> 5
A26: Total Feed | B26: =B24*B19*1000 -> #REF! | C26: kg/hr | Q26: Gasification Cost Assumptions | Y26: Average Salary | Z26: 90000
A27: Solids | B27: =(1-G18)*B26 -> #REF! | C27: kg/hr | E27: Feed Composition (wt % wb) | H27: Non - Combustible | Q27: Feed Rate (kg/hr) | R27: Gassification Costs (KUSD) | S27: TIC Factor | T27: TIC KUSD | U27: TIC KAUD | V27: Maximum GJ/hr
A28: Water In | B28: =B26-B27 -> #REF! | C28: kg/hr | E28: Moisture | F28: Volatile Matter | G28: Fixed Carbon | H28: Ash | I28: Ferrous Metals | J28: Aluminium | Q28: 300 | R28: =850 -> 850 | S28: 2 | T28: =R28*S28 -> 1700 | U28: =T28*$R$18 -> 2550 | V28: 3.4 | Y28: Mgmt OvHd | Z28: 0.1 | AA28: % of SWB
A29: Water Removed | B29: =B28-B30 -> #REF! | C29: kg/hr | E29: =(G20-B29)/(G20-B29+H20+I20+J20+K20+L20) -> #REF! | F29: =H20/(G20-B29+H20+I20+J20+K20+L20) -> #REF! | G29: =I20/(G20-B29+H20+I20+J20+K20+L20) -> #REF! | H29: =J20/(G20-B29+H20+I20+J20+K20+L20) -> #REF! | I29: =K20/(G20-B29+H20+I20+J20+K20+L20) -> #REF! | J29: =L20/(G20-B29+H20+I20+J20+K20+L20) -> #REF! | Q29: 600 | R29: =2*850 -> 1700 | S29: 1.5 | T29: =R29*S29 -> 2550 | U29: =T29*$R$18 -> 3825 | V29: =2*V28 -> 6.8
A30: Water Remaining | B30: =B27/B25-B27 -> #REF! | C30: kg/hr | G30: Total Ash | H30: =SUM(H29:J29) -> #REF! | Q30: 900 | R30: =3*850 -> 2550 | S30: 1.5 | T30: =R30*S30 -> 3825 | U30: =T30*$R$18 -> 5737.5 | V30: 15 | Y30: Energy Requirement | Z30: =50+75*E63/1000+175*B36/5000 -> #REF! | AA30: kW
Q31: 1000 | R31: =2500 -> 2500 | S31: 2 | T31: =R31*S31 -> 5000 | U31: =T31*$R$18 -> 7500 | V31: 15 | Y31: Other | Z31: 10 | AA31: AUD/hr
A32: Dryer | Q32: 1300 | R32: =(850+2500) -> 3350 | S32: 1.5 | T32: =R32*S32 -> 5025 | U32: =T32*$R$18 -> 7537.5 | V32: =V31+V28 -> 18.4
A33: Feed to Dryer | B33: 0 | C33: % of DeW or Blended | E33: Dried Product | M33: Thermal | Q33: 1600 | R33: =(850*2+2500) -> 4200 | S33: 1.5 | T33: =R33*S33 -> 6300 | U33: =T33*$R$18 -> 9450 | V33: =V31+V29 -> 21.8 | Y33: Direct Maintenance | Z33: 0.03 | AA33: % of TIC
A34: Feed to Dryer | B34: =IF(F24>0,B33*F24,B33*B19*1000) -> #REF! | C34: kg/hr | E34: Rate | F34: =B34-B37 -> #REF! | G34: kg/hr | H34: Sold | I34: =F34*F35 -> #REF! | J34: kg/hr | M34: Condensing Service | N34: 0 | O34: Yes/No | Q34: 1900 | R34: =2*2500 -> 5000 | S34: 1.5 | T34: =R34*S34 -> 7500 | U34: =T34*$R$18 -> 11250 | V34: =2*V31 -> 30 | Y34: Accrued Maintenance | Z34: 0.03 | AA34: % of TIC
A35: Water Removal | B35: 0.9 | C35: % | E35: Sale Fraction | F35: 0 | G35: % | H35: NCV AR | I35: =(((N18/1000)*(1-(H39*(1/(1-E39)))/1)*((1-E39)/1))-(0.02443*E39))*1000 -> #REF! | J35: kJ/kg | M35: Recovery | N35: 0.85 | O35: % | Q35: 2000 | R35: =2*2500 -> 5000 | S35: 1.5 | T35: =R35*S35 -> 7500 | U35: =T35*$R$18 -> 11250 | V35: =2*V31 -> 30
A36: Water In | B36: =E29*B34 -> #REF! | C36: kg/hr | M36: Outlet Temp | N36: 120 | O36: deg C | Q36: 2300 | R36: =2*2500+850 -> 5850 | S36: 1.5 | T36: =R36*S36 -> 8775 | U36: =T36*$R$18 -> 13162.5 | V36: =V35+V28 -> 33.4
A37: Water Removed | B37: =B35*B36 -> #REF! | C37: kg/hr | E37: Feed Composition (wt % wb) | H37: Non - Combustible | M37: Specific Heat | N37: 1 | O37: kJ/kg/C | Q37: 2600 | R37: =2*2500+2*850 -> 6700 | S37: 1.5 | T37: =R37*S37 -> 10050 | U37: =T37*$R$18 -> 15075 | V37: =V35+V29 -> 36.8
A38: Water Remaining | B38: =B36-B37 -> #REF! | C38: kg/hr | E38: Moisture | F38: Volatile Matter | G38: Fixed Carbon | H38: Ash | I38: Ferrous Metals | J38: Aluminium | M38: Valuable Energy | N38: =IFERROR(((850-N36)*(E63-E66-E68+F66)*N37+(2260*F68*N34))/1000/1000*N35*(1-MAX(B49,B48)),0) -> 0 | O38: GJ/hr | Q38: 2900 | R38: =3*2500 -> 7500 | S38: 1.5 | T38: =R38*S38 -> 11250 | U38: =T38*$R$18 -> 16875 | V38: 45 | Y38: CAPEX Assumptions
A39: Energy Requirement | B39: =B37*R11/1000/1000 -> #REF! | C39: GJ/hr | E39: =IFERROR(B38/F34,0) -> 0 | F39: =IFERROR(B33*H20/F34,0) -> 0 | G39: =IFERROR(B33*I20/F34,0) -> 0 | H39: =IFERROR(B33*J20/F34,0) -> 0 | I39: =IFERROR(B33*K18/F34,0) -> 0 | J39: =IFERROR(B33*L18/F34,0) -> 0 | M39: Check | N39: =N35*B51 -> #REF! | O39: GJ/hr | Q39: 3000 | R39: =3*2500 -> 7500 | S39: 1.5 | T39: =R39*S39 -> 11250 | U39: =T39*$R$18 -> 16875 | V39: 45 | Z39: CAPEX (AUD)
A40: Gasification Flue | B40: =((B44-B43)/(H66-B43))*B42 -> #REF! | C40: kg/hr | G40: Total Ash | H40: =SUM(H39:J39) -> 0 | Q40: 3300 | R40: =3*2500+850 -> 8350 | S40: 1.5 | T40: =R40*S40 -> 12525 | U40: =T40*$R$18 -> 18787.5 | V40: =V39+V28 -> 48.4 | Y40: Material Handling | Z40: 0
...

Sheet NPV2
A1: Equity Analysis of a Project
E2: INPUT SHEET: USER ENTERS ALL BOLD NUMBERS
A3: INITIAL INVESTMENT | E3: CASHFLOW DETAILS | I3: DISCOUNT RATE
A4: Initial Investment= | C4: ='M2'!B90 -> #REF! | E4: Revenues in year 1= | G4: ='M2'!E83 -> #REF! | I4: Approach(1:Direct;2:CAPM)= | K4: 2
A5: Opportunity cost (if any)= | C5: =#REF! -> #REF! | E5: Var. Expenses as % of Rev= | G5: =SUM('M2'!E85:E86)/'M2'!E83 -> #REF! | I5: 1. Discount rate = | K5: 0.08
A6: Lifetime of the investment | C6: 10 | E6: Fixed expenses in year 1= | G6: ='M2'!E87 -> #REF! | I6: 2a. Beta | K6: 1
A7: Salvage Value at end of project= | C7: 0 | E7: Tax rate on net income= | G7: 0.3 | I7: b. Riskless rate= | K7: 0.04
A8: Deprec. method(1:St.line;2:DDB)= | C8: 1 | E8: If you do not have the breakdown of fixed and variable | I8: c. Market risk premium = | K8: 0.08
A9: Tax Credit (if any )= | C9: 0 | E9: expenses, input the entire expense as a % of revenues. | I9: d. Debt Ratio = | K9: =1-1/'M2'!R21 -> 0.5
A10: Other invest.(non-depreciable)= | C10: 0 | I10: e. Cost of Borrowing = | K10: =#REF! -> #REF!
I11: Discount rate used= | K11: =IF(K4=1,K5,(K7+K6*K8)*(1-K9)+K10*(1-G7)*K9) -> #REF!
A12: WORKING CAPITAL
A13: Initial Investment in Work. Cap= | C13: 0
A14: Working Capital as % of Rev= | C14: 0
A15: Salvageable fraction at end= | C15: 1
A17: GROWTH RATES
C18: 1 | D18: 2 | E18: 3 | F18: 4 | G18: 5 | H18: 6 | I18: 7 | J18: 8 | K18: 9 | L18: 10 | M18: 11 | N18: 12 | O18: 13 | P18: 14 | Q18: 15 | R18: 16 | S18: 17 | T18: 18 | U18: 19 | V18: 20
A19: Revenues | C19: Do not enter | D19: 0.03 | E19: 0.03 | F19: 0.03 | G19: 0.03 | H19: 0.03 | I19: 0.03 | J19: 0.03 | K19: 0.03 | L19: 0.03 | M19: 0.03 | N19: 0.03 | O19: 0.03 | P19: 0.03 | Q19: 0.03 | R19: 0.03 | S19: 0.03 | T19: 0.03 | U19: 0.03 | V19: 0.03
A20: Fixed Expenses | C20: Do not enter | D20: =D19 -> 0.03 | E20: =E19 -> 0.03 | F20: =F19 -> 0.03 | G20: =G19 -> 0.03 | H20: =H19 -> 0.03 | I20: =I19 -> 0.03 | J20: =J19 -> 0.03 | K20: =K19 -> 0.03 | ... V20: =V19 -> 0.03
A21: Default: The fixed expense growth rate is set equal to the growth rate in revenues by default.
F22: YEAR
B23: 0 | C23: 1 | D23: 2 | E23: 3 | F23: 4 | G23: 5 | H23: 6 | I23: 7 | J23: 8 | K23: 9 | L23: 10 | M23: 11 | N23: 12 | O23: 13 | P23: 14 | Q23: 15 | R23: 16 | S23: 17 | T23: 18 | U23: 19 | V23: 20
A24: INVESTMENTS
A25: Investment | B25: =C4 -> #REF!
A26: - Tax Credit | B26: =C4*C9 -> #REF!
A27: Net Investment | B27: =B25-B26 -> #REF!
A28: + Working Cap | B28: =C13 -> 0
A29: + Opp. Cost | B29: =C5 -> #REF!
A30: + Other invest. | B30: =C10 -> 0
A31: Investments | B31: =B27+B28+B29+B30 -> #REF!
A33: SALVAGE VALUE
A34: Equipment | C34: =IF(C23=$C$6,$C$7,0) -> 0 | D34: =IF(D23=$C$6,$C$7,0) -> 0 | E34: =IF(E23=$C$6,$C$7,0) -> 0 | F34: =IF(F23=$C$6,$C$7,0) -> 0 | G34: =IF(G23=$C$6,$C$7,0) -> 0 | H34: =IF(H23=$C$6,$C$7,0) -> 0 | I34: =IF(I23=$C$6,$C$7,0) -> 0 | J34: =IF(J23=$C$6,$C$7,0) -> 0 | ... V34: =IF(V23=$C$6,$C$7,0) -> 0
A35: Working Capital | C35: =IF(C23=$C$6,($C$13+SUM($C$48:$V$48))*$C$15,0) -> 0 | D35: =IF(D23=$C$6,($C$13+SUM($C$48:$V$48))*$C$15,0) -> 0 | E35: =IF(E23=$C$6,($C$13+SUM($C$48:$V$48))*$C$15,0) -> 0 | F35: =IF(F23=$C$6,($C$13+SUM($C$48:$V$48))*$C$15,0) -> 0 | G35: =IF(G23=$C$6,($C$13+SUM($C$48:$V$48))*$C$15,0) -> 0 | H35: =IF(H23=$C$6,($C$13+SUM($C$48:$V$48))*$C$15,0) -> 0 | I35: =IF(I23=$C$6,($C$13+SUM($C$48:$V$48))*$C$15,0) -> 0 | J35: =IF(J23=$C$6,($C$13+SUM($C$48:$V$48))*$C$15,0) -> 0 | ... V35: =IF(V23=$C$6,($C$13+SUM($C$48:$V$48))*$C$15,0) -> 0
A37: OPERATING CASHFLOWS
A38: Lifetime Index | C38: =IF(C23>$C$6,0,1) -> 1 | D38: =IF(D23>$C$6,0,1) -> 1 | E38: =IF(E23>$C$6,0,1) -> 1 | F38: =IF(F23>$C$6,0,1) -> 1 | G38: =IF(G23>$C$6,0,1) -> 1 | H38: =IF(H23>$C$6,0,1) -> 1 | I38: =IF(I23>$C$6,0,1) -> 1 | J38: =IF(J23>$C$6,0,1) -> 1 | ... V38: =IF(V23>$C$6,0,1) -> 0
A39: Revenues | C39: =G4 -> #REF! | D39: =C39*(1+D19)*D38 -> #REF! | E39: =D39*(1+E19)*E38 -> #REF! | F39: =E39*(1+F19)*F38 -> #REF! | G39: =F39*(1+G19)*G38 -> #REF! | H39: =G39*(1+H19)*H38 -> #REF! | I39: =H39*(1+I19)*I38 -> #REF! | J39: =I39*(1+J19)*J38 -> #REF! | K39: =J39*(1+K19)*K38 -> #REF! | ... V39: =U39*(1+V19)*V38 -> #REF!
A40: -Var. Expenses | C40: =C39*$G$5 -> #REF! | D40: =D39*$G$5 -> #REF! | E40: =E39*$G$5 -> #REF! | F40: =F39*$G$5 -> #REF! | G40: =G39*$G$5 -> #REF! | H40: =H39*$G$5 -> #REF! | I40: =I39*$G$5 -> #REF! | J40: =J39*$G$5 -> #REF! | ... V40: =V39*$G$5 -> #REF!
A41: - Fixed Expenses | C41: =G6 -> #REF! | D41: =C41*(1+D20)*D38 -> #REF! | E41: =D41*(1+E20)*E38 -> #REF! | F41: =E41*(1+F20)*F38 -> #REF! | G41: =F41*(1+G20)*G38 -> #REF! | H41: =G41*(1+H20)*H38 -> #REF! | I41: =H41*(1+I20)*I38 -> #REF! | J41: =I41*(1+J20)*J38 -> #REF! | K41: =J41*(1+K20)*K38 -> #REF! | ... V41: =U41*(1+V20)*V38 -> #REF!
A42: EBITDA | C42: =C39-C40-C41 -> #REF! | D42: =D39-D40-D41 -> #REF! | E42: =E39-E40-E41 -> #REF! | F42: =F39-F40-F41 -> #REF! | G42: =G39-G40-G41 -> #REF! | H42: =H39-H40-H41 -> #REF! | I42: =I39-I40-I41 -> #REF! | J42: =J39-J40-J41 -> #REF! | ... V42: =V39-V40-V41 -> #REF!
A43: - Depreciation | C43: =C61 -> #REF! | D43: =D61 -> #REF! | E43: =E61 -> #REF! | F43: =F61 -> #REF! | G43: =G61 -> #REF! | H43: =H61 -> #REF! | I43: =I61 -> #REF! | J43: =J61 -> #REF! | ... V43: =V61 -> #REF!
...
